[ERROR] - 2025-02-16 14:45:55,048 - root - ea020bfd-a29b-41c1-aec0-8158dd5d22a1 'AuthorizationManager' object has no attribute 'is_deleted'
[ERROR] - 2025-02-16 14:48:42,462 - root - ea020bfd-a29b-41c1-aec0-8158dd5d22a1 'AuthorizationManager' object has no attribute 'is_deleted'
[ERROR] - 2025-02-16 14:50:07,020 - root - d5cb6f7f-a83e-4d44-9377-aefedf88af4f 'AuthorizationManager' object has no attribute 'is_deleted'
[ERROR] - 2025-02-16 14:52:34,881 - root - 1923d416-2cac-4d75-a880-57d851d16d62 'AuthorizationManager' object has no attribute 'is_deleted'
[ERROR] - 2025-02-16 14:52:54,203 - root - 1923d416-2cac-4d75-a880-57d851d16d62 'AuthorizationManager' object has no attribute 'is_deleted'
[ERROR] - 2025-02-16 14:54:02,585 - root - 1923d416-2cac-4d75-a880-57d851d16d62 'AuthorizationManager' object has no attribute 'is_deleted'
[ERROR] - 2025-02-16 14:58:02,897 - root - 42a1380e-33ee-473e-a2d4-ae27024cca66 'AuthorizationManager' object has no attribute 'is_deleted'
[ERROR] - 2025-02-16 15:00:06,418 - root - 42a1380e-33ee-473e-a2d4-ae27024cca66 'AuthorizationManager' object has no attribute 'is_deleted'
[ERROR] - 2025-02-16 15:00:46,553 - root - f8e8a6aa-20dc-4ecd-ab51-5600f915ee86 'AuthorizationManager' object has no attribute 'is_deleted'
[ERROR] - 2025-02-16 16:29:04,254 - root - 2483a458-235a-44b6-babd-8163ba3b4f40 Could not initialize target column for ForeignKey 'tunnel.id' on table 'interface': table 'tunnel' has no column named 'id'
[ERROR] - 2025-02-16 16:33:22,202 - root - 90b57f25-d922-4dc4-ac02-63a1433e3be9 reverse_property 'device' on relationship Tunnel.interfaces references relationship Interface.device, which does not reference mapper Mapper[Tunnel(tunnel)]
[ERROR] - 2025-02-16 16:35:37,165 - root - e0c26d45-f48f-46a8-af57-1b54d5a41549 (sqlalchemy.dialects.postgresql.asyncpg.Error) <class 'asyncpg.exceptions.DataError'>: invalid input for query argument $7: UUID('d30ea2dc-f805-4693-9822-eeab908512... (expected str, got UUID)
[SQL: INSERT INTO "user" (id, name, password, admin, is_deleted, created_at, created_by, modified_at, modified_by, deleted_at, deleted_by) VALUES ($1::UUID, $2::VARCHAR, $3::VARCHAR, $4::BOOLEAN, $5::BOOLEAN, $6::TIMESTAMP WITHOUT TIME ZONE, $7::VARCHAR, $8::TIMESTAMP WITHOUT TIME ZONE, $9::VARCHAR, $10::TIMESTAMP WITHOUT TIME ZONE, $11::VARCHAR)]
[parameters: (UUID('6b2b2d14-cbbf-4118-83bd-209d383ff5c4'), 'hanoch2', '$2b$12$OGrvJRkMHpsvmGa7SygGI.4XGolfmpX6Es5f1X9Jy6AMm9pSh0tHW', True, False, datetime.datetime(2025, 2, 16, 16, 35, 37, 154560), UUID('d30ea2dc-f805-4693-9822-eeab9085127b'), datetime.datetime(2025, 2, 16, 16, 35, 37, 154560), UUID('d30ea2dc-f805-4693-9822-eeab9085127b'), None, None)]
(Background on this error at: https://sqlalche.me/e/20/dbapi)
[ERROR] - 2025-02-16 16:38:37,596 - root - dcff1bf7-0d1c-4087-a2b6-7c77e4731ceb (sqlalchemy.dialects.postgresql.asyncpg.Error) <class 'asyncpg.exceptions.DataError'>: invalid input for query argument $7: UUID('0f365702-81d3-4b10-a31e-acc6518526... (expected str, got UUID)
[SQL: INSERT INTO "user" (id, name, password, admin, is_deleted, created_at, created_by, modified_at, modified_by, deleted_at, deleted_by) VALUES ($1::UUID, $2::VARCHAR, $3::VARCHAR, $4::BOOLEAN, $5::BOOLEAN, $6::TIMESTAMP WITHOUT TIME ZONE, $7::VARCHAR, $8::TIMESTAMP WITHOUT TIME ZONE, $9::VARCHAR, $10::TIMESTAMP WITHOUT TIME ZONE, $11::VARCHAR)]
[parameters: (UUID('fcda7ff0-9bf6-40d9-9877-525a342afdba'), 'hanoch2', '$2b$12$SXBm2J1gfrGBsqLGPyi6zOV3Buo/xKp3ASQYc.WQyNuurPsMbAqMC', True, False, datetime.datetime(2025, 2, 16, 16, 38, 37, 592330), UUID('0f365702-81d3-4b10-a31e-acc65185260b'), datetime.datetime(2025, 2, 16, 16, 38, 37, 592330), UUID('0f365702-81d3-4b10-a31e-acc65185260b'), None, None)]
(Background on this error at: https://sqlalche.me/e/20/dbapi)
[ERROR] - 2025-02-16 16:39:54,790 - root - a880e695-6c77-47f8-aa96-356e166f0729 (sqlalchemy.dialects.postgresql.asyncpg.Error) <class 'asyncpg.exceptions.DataError'>: invalid input for query argument $7: UUID('f1ffa77e-34f0-4db2-bf27-0ff2c2f65f... (expected str, got UUID)
[SQL: INSERT INTO "user" (id, name, password, admin, is_deleted, created_at, created_by, modified_at, modified_by, deleted_at, deleted_by) VALUES ($1::UUID, $2::VARCHAR, $3::VARCHAR, $4::BOOLEAN, $5::BOOLEAN, $6::TIMESTAMP WITHOUT TIME ZONE, $7::VARCHAR, $8::TIMESTAMP WITHOUT TIME ZONE, $9::VARCHAR, $10::TIMESTAMP WITHOUT TIME ZONE, $11::VARCHAR)]
[parameters: (UUID('0e420bc9-2e50-48a6-8faa-0dbcb841fd9b'), 'hanoch2', '$2b$12$J3WWaAKkD4rgTZIS2xqT7eHHtGfxD/jnFgomsMrp3aOMM13TVuu2e', True, False, datetime.datetime(2025, 2, 16, 16, 39, 54, 786389), UUID('f1ffa77e-34f0-4db2-bf27-0ff2c2f65f61'), datetime.datetime(2025, 2, 16, 16, 39, 54, 786389), UUID('f1ffa77e-34f0-4db2-bf27-0ff2c2f65f61'), None, None)]
(Background on this error at: https://sqlalche.me/e/20/dbapi)
[ERROR] - 2025-02-19 11:53:24,100 - root - 002ba3d2-de86-4cb4-9fd4-523c11459d9f 1 validation errors:
  {'type': 'model_attributes_type', 'loc': ('response',), 'msg': 'Input should be a valid dictionary or object to extract fields from', 'input': None, 'url': 'https://errors.pydantic.dev/2.7/v/model_attributes_type'}

[ERROR] - 2025-02-19 12:06:30,063 - root - 002ba3d2-de86-4cb4-9fd4-523c11459d9f 1 validation errors:
  {'type': 'model_attributes_type', 'loc': ('response',), 'msg': 'Input should be a valid dictionary or object to extract fields from', 'input': None, 'url': 'https://errors.pydantic.dev/2.7/v/model_attributes_type'}

[ERROR] - 2025-02-19 12:06:37,500 - root - 002ba3d2-de86-4cb4-9fd4-523c11459d9f 1 validation errors:
  {'type': 'model_attributes_type', 'loc': ('response',), 'msg': 'Input should be a valid dictionary or object to extract fields from', 'input': None, 'url': 'https://errors.pydantic.dev/2.7/v/model_attributes_type'}

[ERROR] - 2025-02-19 12:08:12,443 - root - 002ba3d2-de86-4cb4-9fd4-523c11459d9f 1 validation errors:
  {'type': 'model_attributes_type', 'loc': ('response',), 'msg': 'Input should be a valid dictionary or object to extract fields from', 'input': None, 'url': 'https://errors.pydantic.dev/2.7/v/model_attributes_type'}

[ERROR] - 2025-02-19 12:18:08,121 - root - 002ba3d2-de86-4cb4-9fd4-523c11459d9f 1 validation errors:
  {'type': 'model_attributes_type', 'loc': ('response',), 'msg': 'Input should be a valid dictionary or object to extract fields from', 'input': None, 'url': 'https://errors.pydantic.dev/2.7/v/model_attributes_type'}

[ERROR] - 2025-02-19 12:18:10,531 - root - 002ba3d2-de86-4cb4-9fd4-523c11459d9f 1 validation errors:
  {'type': 'model_attributes_type', 'loc': ('response',), 'msg': 'Input should be a valid dictionary or object to extract fields from', 'input': None, 'url': 'https://errors.pydantic.dev/2.7/v/model_attributes_type'}

[ERROR] - 2025-02-19 12:23:00,887 - root - 002ba3d2-de86-4cb4-9fd4-523c11459d9f 1 validation errors:
  {'type': 'model_attributes_type', 'loc': ('response',), 'msg': 'Input should be a valid dictionary or object to extract fields from', 'input': None, 'url': 'https://errors.pydantic.dev/2.7/v/model_attributes_type'}

[ERROR] - 2025-02-19 12:34:24,462 - root - 03d30143-15d2-4fa3-885d-c316e30939b6 1 validation errors:
  {'type': 'model_attributes_type', 'loc': ('response',), 'msg': 'Input should be a valid dictionary or object to extract fields from', 'input': None, 'url': 'https://errors.pydantic.dev/2.7/v/model_attributes_type'}

[ERROR] - 2025-02-19 12:38:10,350 - root - 03d30143-15d2-4fa3-885d-c316e30939b6 1 validation errors:
  {'type': 'model_attributes_type', 'loc': ('response',), 'msg': 'Input should be a valid dictionary or object to extract fields from', 'input': None, 'url': 'https://errors.pydantic.dev/2.7/v/model_attributes_type'}

[ERROR] - 2025-02-19 12:38:43,997 - root - efb45782-4a00-40c4-b6d4-be8949dd5aea 1 validation errors:
  {'type': 'model_attributes_type', 'loc': ('response',), 'msg': 'Input should be a valid dictionary or object to extract fields from', 'input': None, 'url': 'https://errors.pydantic.dev/2.7/v/model_attributes_type'}

[ERROR] - 2025-02-19 12:47:07,223 - root - f54e6ced-d151-45a7-b18c-4a75e95b30a5 1 validation errors:
  {'type': 'model_attributes_type', 'loc': ('response',), 'msg': 'Input should be a valid dictionary or object to extract fields from', 'input': None, 'url': 'https://errors.pydantic.dev/2.7/v/model_attributes_type'}

[ERROR] - 2025-02-19 12:50:03,872 - root - f54e6ced-d151-45a7-b18c-4a75e95b30a5 1 validation errors:
  {'type': 'model_attributes_type', 'loc': ('response',), 'msg': 'Input should be a valid dictionary or object to extract fields from', 'input': None, 'url': 'https://errors.pydantic.dev/2.7/v/model_attributes_type'}

[ERROR] - 2025-02-19 12:50:55,251 - root - f54e6ced-d151-45a7-b18c-4a75e95b30a5 1 validation errors:
  {'type': 'model_attributes_type', 'loc': ('response',), 'msg': 'Input should be a valid dictionary or object to extract fields from', 'input': None, 'url': 'https://errors.pydantic.dev/2.7/v/model_attributes_type'}

[ERROR] - 2025-02-19 12:51:54,271 - root - 895a44bd-7428-40af-b265-a7d5cd9747e3 1 validation errors:
  {'type': 'model_attributes_type', 'loc': ('response',), 'msg': 'Input should be a valid dictionary or object to extract fields from', 'input': None, 'url': 'https://errors.pydantic.dev/2.7/v/model_attributes_type'}

[ERROR] - 2025-02-19 12:52:53,083 - root - 247785ba-8564-437e-982d-e67a4dededbf 1 validation errors:
  {'type': 'model_attributes_type', 'loc': ('response',), 'msg': 'Input should be a valid dictionary or object to extract fields from', 'input': None, 'url': 'https://errors.pydantic.dev/2.7/v/model_attributes_type'}

[ERROR] - 2025-02-19 12:53:30,281 - root - 38c08d39-2c73-4fc0-b5f7-d21830420574 1 validation errors:
  {'type': 'model_attributes_type', 'loc': ('response',), 'msg': 'Input should be a valid dictionary or object to extract fields from', 'input': None, 'url': 'https://errors.pydantic.dev/2.7/v/model_attributes_type'}

[ERROR] - 2025-02-19 12:54:12,896 - root - 4339adb4-1ddd-4e1f-bc10-bfd53f540b83 1 validation errors:
  {'type': 'model_attributes_type', 'loc': ('response',), 'msg': 'Input should be a valid dictionary or object to extract fields from', 'input': None, 'url': 'https://errors.pydantic.dev/2.7/v/model_attributes_type'}

[ERROR] - 2025-02-19 12:58:40,499 - root - c79149fd-0c43-4f2c-b860-66accb18db66 1 validation errors:
  {'type': 'model_attributes_type', 'loc': ('response',), 'msg': 'Input should be a valid dictionary or object to extract fields from', 'input': None, 'url': 'https://errors.pydantic.dev/2.7/v/model_attributes_type'}

[ERROR] - 2025-02-19 12:59:25,973 - root - 3b1e179b-1941-439a-94ba-68bcd7c460b6 1 validation errors:
  {'type': 'model_attributes_type', 'loc': ('response',), 'msg': 'Input should be a valid dictionary or object to extract fields from', 'input': None, 'url': 'https://errors.pydantic.dev/2.7/v/model_attributes_type'}

[ERROR] - 2025-02-19 12:59:57,351 - root - ecdbdf54-913f-491d-991d-312276469331 1 validation errors:
  {'type': 'model_attributes_type', 'loc': ('response',), 'msg': 'Input should be a valid dictionary or object to extract fields from', 'input': None, 'url': 'https://errors.pydantic.dev/2.7/v/model_attributes_type'}

[ERROR] - 2025-02-19 14:08:47,333 - root - 04ae9fda-e2ab-43fd-8f78-2bb6b11d69fe 1 validation errors:
  {'type': 'model_attributes_type', 'loc': ('response',), 'msg': 'Input should be a valid dictionary or object to extract fields from', 'input': None, 'url': 'https://errors.pydantic.dev/2.7/v/model_attributes_type'}

[ERROR] - 2025-02-19 14:12:06,391 - root - f114b0c9-24a5-425c-9381-a27054422c59 1 validation errors:
  {'type': 'model_attributes_type', 'loc': ('response',), 'msg': 'Input should be a valid dictionary or object to extract fields from', 'input': None, 'url': 'https://errors.pydantic.dev/2.7/v/model_attributes_type'}

[ERROR] - 2025-02-19 14:13:26,152 - root - 5e1773a4-6873-440a-a3ee-28b23b5e27b1 1 validation errors:
  {'type': 'model_attributes_type', 'loc': ('response',), 'msg': 'Input should be a valid dictionary or object to extract fields from', 'input': None, 'url': 'https://errors.pydantic.dev/2.7/v/model_attributes_type'}

[ERROR] - 2025-02-19 15:02:19,900 - root - ccd27940-96c9-4009-94f1-a3d6087d7231 1 validation errors:
  {'type': 'model_attributes_type', 'loc': ('response',), 'msg': 'Input should be a valid dictionary or object to extract fields from', 'input': None, 'url': 'https://errors.pydantic.dev/2.7/v/model_attributes_type'}

[ERROR] - 2025-02-19 15:02:45,305 - root - ccd27940-96c9-4009-94f1-a3d6087d7231 1 validation errors:
  {'type': 'model_attributes_type', 'loc': ('response',), 'msg': 'Input should be a valid dictionary or object to extract fields from', 'input': None, 'url': 'https://errors.pydantic.dev/2.7/v/model_attributes_type'}

[ERROR] - 2025-02-19 15:03:24,401 - root - 7cb481fd-8dca-48e3-bb85-ca0db9fa72b8 1 validation errors:
  {'type': 'model_attributes_type', 'loc': ('response',), 'msg': 'Input should be a valid dictionary or object to extract fields from', 'input': None, 'url': 'https://errors.pydantic.dev/2.7/v/model_attributes_type'}

[ERROR] - 2025-02-19 15:07:37,762 - root - f8e2035d-7b57-4ffe-8a65-33555ac7da9a 1 validation errors:
  {'type': 'model_attributes_type', 'loc': ('response',), 'msg': 'Input should be a valid dictionary or object to extract fields from', 'input': None, 'url': 'https://errors.pydantic.dev/2.7/v/model_attributes_type'}

[ERROR] - 2025-02-19 15:08:16,012 - root - 785eda6d-4e21-4d51-a231-5235d077909d 1 validation errors:
  {'type': 'model_attributes_type', 'loc': ('response',), 'msg': 'Input should be a valid dictionary or object to extract fields from', 'input': None, 'url': 'https://errors.pydantic.dev/2.7/v/model_attributes_type'}

[ERROR] - 2025-02-19 15:10:02,313 - root - ea33092c-a560-4a73-9aff-dbddbc333cd6 1 validation errors:
  {'type': 'model_attributes_type', 'loc': ('response',), 'msg': 'Input should be a valid dictionary or object to extract fields from', 'input': None, 'url': 'https://errors.pydantic.dev/2.7/v/model_attributes_type'}

[ERROR] - 2025-02-19 15:12:12,766 - root - c7906bb7-ecb2-4116-8125-96f26fdf5db0 1 validation errors:
  {'type': 'model_attributes_type', 'loc': ('response',), 'msg': 'Input should be a valid dictionary or object to extract fields from', 'input': None, 'url': 'https://errors.pydantic.dev/2.7/v/model_attributes_type'}

[ERROR] - 2025-02-19 16:04:43,946 - root - f0bbea7e-6080-4969-9833-0d0163f9dc15 'AuthorizationManager' object has no attribute 'is_deleted'
[ERROR] - 2025-02-19 16:25:23,516 - root - 30e721ea-1282-4b00-9103-3a642f8ea457 'AuthorizationManager' object has no attribute 'is_deleted'
[ERROR] - 2025-02-19 16:26:46,766 - root - f931bd74-0703-4c76-8d4e-6b71e4c306ba 'AuthorizationManager' object has no attribute 'is_deleted'
[ERROR] - 2025-02-19 16:31:45,506 - root - 4a2324fe-6e40-462b-aae5-26fdb13e5b85 'AuthorizationManager' object has no attribute 'is_deleted'
[ERROR] - 2025-02-19 17:11:02,087 - root - b3ef2fe4-a6d4-4bbb-ac37-9fd1a3cba627 1 validation error for OAuthBearerToken
access_token
  Field required [type=missing, input_value={'data': 'eyJhbGciOiJIUzI...XsoSQX000Jg2VvbE3cOBeE'}, input_type=dict]
    For further information visit https://errors.pydantic.dev/2.7/v/missing
[ERROR] - 2025-02-19 17:12:32,949 - root - b3ef2fe4-a6d4-4bbb-ac37-9fd1a3cba627 1 validation error for OAuthBearerToken
access_token
  Field required [type=missing, input_value={'data': 'eyJhbGciOiJIUzI...XsoSQX000Jg2VvbE3cOBeE'}, input_type=dict]
    For further information visit https://errors.pydantic.dev/2.7/v/missing
[ERROR] - 2025-02-19 17:45:38,253 - root - be864ea2-0d2b-4343-8c5f-2ac6af8f0f5a 'coroutine' object has no attribute 'is_deleted'
[ERROR] - 2025-02-19 17:47:13,645 - root - be864ea2-0d2b-4343-8c5f-2ac6af8f0f5a 'coroutine' object has no attribute 'is_deleted'
[ERROR] - 2025-02-19 17:50:30,222 - root - 78d01624-fffa-4a3f-ab83-c22486207de1 'coroutine' object has no attribute 'is_deleted'
[ERROR] - 2025-02-19 18:11:04,449 - root - de075f70-1f1d-40fd-b972-1d92841dac3c object dict can't be used in 'await' expression
[ERROR] - 2025-02-19 18:19:58,035 - root - b12d4dd4-02b0-4b9c-9ce7-83a447339109 cannot access local variable 'data' where it is not associated with a value
[ERROR] - 2025-02-19 18:24:48,474 - root - 99b4bb25-2542-4015-aa2f-200630d32f1a cannot access local variable 'data' where it is not associated with a value
[ERROR] - 2025-02-19 18:31:48,396 - root - b3d79783-39c5-4fd4-a446-13994f61526c BaseModel.__init__() takes 1 positional argument but 2 were given
[ERROR] - 2025-02-19 18:33:20,425 - root - d8d7b3cb-0b1d-419a-853f-478611e94255 cannot access local variable 'data' where it is not associated with a value
[ERROR] - 2025-02-19 19:41:26,998 - root - a391d5d1-14ce-4ca9-b564-a0c27849acd9 'dict' object has no attribute 'sub'
[ERROR] - 2025-02-19 19:42:20,658 - root - 2ca11651-435c-44ab-a96a-2fa986f4d85d 'async_generator' object has no attribute 'execute'
[ERROR] - 2025-02-19 19:46:39,989 - root - 22fa3130-61ec-4b9e-9967-2f77e5e0a81f 'async_generator' object has no attribute 'execute'
[ERROR] - 2025-02-19 19:48:06,965 - root - 16367d32-c2a3-46bd-96f7-95dea9933613 'async_generator' object has no attribute 'execute'
[ERROR] - 2025-02-19 19:49:41,742 - root - 28144432-6f1d-4125-ab93-407e7331f722 object async_generator can't be used in 'await' expression
[ERROR] - 2025-02-19 20:01:26,771 - root - feb0f1e7-65dc-4ec2-9a32-6a08d915e72a BaseModel.__init__() takes 1 positional argument but 2 were given
[ERROR] - 2025-02-19 20:04:21,705 - root - a0f4ca77-eb53-4f39-aeda-2c1f2def3bac api.main.types.user.UserPrivate() argument after ** must be a mapping, not list
[ERROR] - 2025-02-19 20:04:49,767 - root - acaac6ec-fd12-4d5c-8f17-b2f8602f5dd4 1 validation error for UserPrivate
  Input should be a valid dictionary or instance of UserPrivate [type=model_type, input_value=<dal.models.user.User obj...t at 0x0000021F33840890>, input_type=User]
    For further information visit https://errors.pydantic.dev/2.7/v/model_type
[ERROR] - 2025-02-19 20:05:16,295 - root - cabe8faf-88be-414b-91cb-faa88a79b786 api.main.types.user.UserPrivate() argument after ** must be a mapping, not User
[ERROR] - 2025-02-19 20:05:41,415 - root - cabe8faf-88be-414b-91cb-faa88a79b786 api.main.types.user.UserPrivate() argument after ** must be a mapping, not User
[ERROR] - 2025-02-19 20:08:45,579 - root - 90fe2d49-3d6b-4c85-a4cf-76d57c31c496 'coroutine' object is not subscriptable
[ERROR] - 2025-02-19 20:08:53,782 - root - c2038fd8-d767-45e3-95dd-c2f38d62f0f6 'coroutine' object is not subscriptable
[ERROR] - 2025-02-19 20:09:55,442 - root - c2038fd8-d767-45e3-95dd-c2f38d62f0f6 'coroutine' object is not subscriptable
[ERROR] - 2025-02-19 20:09:58,855 - root - 8a669bab-6f03-4fc0-b653-f130ff042db7 3 validation errors for UserPrivate
created_by
  Input should be a valid string [type=string_type, input_value=UUID('8453c2de-bc7c-44db-a775-967c96f63cb4'), input_type=UUID]
    For further information visit https://errors.pydantic.dev/2.7/v/string_type
modified_by
  Input should be a valid string [type=string_type, input_value=UUID('8453c2de-bc7c-44db-a775-967c96f63cb4'), input_type=UUID]
    For further information visit https://errors.pydantic.dev/2.7/v/string_type
deleted_by
  Input should be a valid string [type=string_type, input_value=UUID('cd4cb58e-97ff-4613-bc63-28074b1d40fc'), input_type=UUID]
    For further information visit https://errors.pydantic.dev/2.7/v/string_type
[ERROR] - 2025-02-19 20:12:05,100 - root - 8a669bab-6f03-4fc0-b653-f130ff042db7 3 validation errors for UserPrivate
created_by
  Input should be a valid string [type=string_type, input_value=UUID('8453c2de-bc7c-44db-a775-967c96f63cb4'), input_type=UUID]
    For further information visit https://errors.pydantic.dev/2.7/v/string_type
modified_by
  Input should be a valid string [type=string_type, input_value=UUID('8453c2de-bc7c-44db-a775-967c96f63cb4'), input_type=UUID]
    For further information visit https://errors.pydantic.dev/2.7/v/string_type
deleted_by
  Input should be a valid string [type=string_type, input_value=UUID('cd4cb58e-97ff-4613-bc63-28074b1d40fc'), input_type=UUID]
    For further information visit https://errors.pydantic.dev/2.7/v/string_type
[ERROR] - 2025-02-19 20:26:09,803 - root - 684c3635-6f05-4249-bdb9-798b02dda979 (sqlalchemy.dialects.postgresql.asyncpg.Error) <class 'asyncpg.exceptions.DataError'>: invalid input for query argument $5: 0 ('int' object has no attribute 'bytes')
[SQL: INSERT INTO device_type (id, name, is_deleted, created_at, created_by, modified_at, modified_by, deleted_at, deleted_by) VALUES ($1::UUID, $2::VARCHAR, $3::BOOLEAN, $4::TIMESTAMP WITHOUT TIME ZONE, $5::UUID, $6::TIMESTAMP WITHOUT TIME ZONE, $7::UUID, $8::TIMESTAMP WITHOUT TIME ZONE, $9::UUID)]
[parameters: (UUID('7cea0965-162e-4682-bee6-09e7532b5582'), 'company1', False, datetime.datetime(2025, 2, 19, 20, 26, 9, 799842), 0, datetime.datetime(2025, 2, 19, 20, 26, 9, 799842), 0, None, UUID('d73db861-01bc-4152-aa77-f50723548b52'))]
(Background on this error at: https://sqlalche.me/e/20/dbapi)
[ERROR] - 2025-02-20 15:08:13,385 - root - 0263b3e1-3d7d-4fec-b640-b2f7a5f92d9d cannot access local variable 'data' where it is not associated with a value
[ERROR] - 2025-02-20 15:40:14,939 - root - ae0e861b-c052-455f-8ae1-948a610009c9 badly formed hexadecimal UUID string
[ERROR] - 2025-02-20 16:40:53,411 - root - 753fd799-c09f-49fa-88d9-ad22dfd2a3d8 BaseModel.__init__() takes 1 positional argument but 2 were given
[ERROR] - 2025-02-20 16:41:53,247 - root - cc445194-e04d-422b-8b52-1cab9ea86516 DeviceTypeController.read_all() missing 1 required positional argument: 'current_user'
[ERROR] - 2025-02-20 16:43:01,023 - root - a259e8cf-7877-4543-b25b-939b9b2d0e0f BaseModel.__init__() takes 1 positional argument but 2 were given
[ERROR] - 2025-02-20 16:44:49,959 - root - a259e8cf-7877-4543-b25b-939b9b2d0e0f BaseModel.__init__() takes 1 positional argument but 2 were given
[ERROR] - 2025-02-20 16:44:56,299 - root - 0004852e-645d-46f7-8773-38d984403a16 api.main.types.device_type.DeviceTypePublic() argument after ** must be a mapping, not DeviceType
[ERROR] - 2025-02-20 16:45:23,834 - root - dd6d5707-8c51-41fb-839f-38e1ae0bc8af 1 validation errors:
  {'type': 'model_attributes_type', 'loc': ('response',), 'msg': 'Input should be a valid dictionary or object to extract fields from', 'input': [DeviceTypePublic(id=UUID('678d958c-dee9-4034-a53b-2f0942a84e09'), name='company1'), DeviceTypePublic(id=UUID('d286ad38-4200-466f-b80a-b493cd193cbc'), name='company2')], 'url': 'https://errors.pydantic.dev/2.7/v/model_attributes_type'}

[ERROR] - 2025-02-24 15:16:38,827 - root - 26c022db-0c80-4560-b1b4-8fad759a83d1 UserController.read_all() got an unexpected keyword argument 'current_user'
[ERROR] - 2025-02-24 15:24:54,425 - root - 26c022db-0c80-4560-b1b4-8fad759a83d1 UserController.read_all() got an unexpected keyword argument 'current_user'
[ERROR] - 2025-02-24 15:25:01,162 - root - 47a147eb-242f-4f35-9100-25178dddd20c 1 validation errors:
  {'type': 'model_attributes_type', 'loc': ('response',), 'msg': 'Input should be a valid dictionary or object to extract fields from', 'input': [UserPublic(id=UUID('601b0a97-d216-426a-806a-1841a12f303a'), name='hanoch2', admin=True), UserPublic(id=UUID('3997276c-7da6-4e09-ae86-1851a35276a5'), name='hanoch', admin=True), UserPublic(id=UUID('62e78253-1c3b-4bcd-a58e-aaf47cb3a347'), name='hanoch', admin=True), UserPublic(id=UUID('02e7dcc0-18bc-45a1-8c6c-bead011954da'), name='hanoch', admin=True), UserPublic(id=UUID('e4f28c0a-568e-4866-815a-ae4083488625'), name='hanoch2', admin=True), UserPublic(id=UUID('7cd8db19-2862-402b-96e1-3d25e3222ca1'), name='hanoch212', admin=True)], 'url': 'https://errors.pydantic.dev/2.7/v/model_attributes_type'}

[ERROR] - 2025-02-24 15:27:19,631 - root - 47a147eb-242f-4f35-9100-25178dddd20c 1 validation errors:
  {'type': 'model_attributes_type', 'loc': ('response',), 'msg': 'Input should be a valid dictionary or object to extract fields from', 'input': [UserPublic(id=UUID('601b0a97-d216-426a-806a-1841a12f303a'), name='hanoch2', admin=True), UserPublic(id=UUID('3997276c-7da6-4e09-ae86-1851a35276a5'), name='hanoch', admin=True), UserPublic(id=UUID('62e78253-1c3b-4bcd-a58e-aaf47cb3a347'), name='hanoch', admin=True), UserPublic(id=UUID('02e7dcc0-18bc-45a1-8c6c-bead011954da'), name='hanoch', admin=True), UserPublic(id=UUID('e4f28c0a-568e-4866-815a-ae4083488625'), name='hanoch2', admin=True), UserPublic(id=UUID('7cd8db19-2862-402b-96e1-3d25e3222ca1'), name='hanoch212', admin=True)], 'url': 'https://errors.pydantic.dev/2.7/v/model_attributes_type'}

[ERROR] - 2025-02-24 15:36:41,149 - root - 016b2157-a6c9-463a-9c4f-4a62be944009 SiteController.read_all() got an unexpected keyword argument 'current_user'
[ERROR] - 2025-02-24 15:37:02,252 - root - a9d5f25f-44bd-4015-a724-e45038c27928 Column expression, FROM clause, or other columns clause element expected, got type[dal.models.site.Site].
[ERROR] - 2025-02-24 15:38:14,287 - root - 20521625-ddb5-4f11-8509-a86d0b0dcb80 Column expression, FROM clause, or other columns clause element expected, got type[dal.models.site.Site].
[ERROR] - 2025-02-24 15:38:37,049 - root - 5bcbcc5e-5d12-4521-b85f-7d0b6a26986e Column expression, FROM clause, or other columns clause element expected, got type[dal.models.site.Site].
[ERROR] - 2025-02-26 16:26:49,640 - root - d1b9a91a-3fd3-44b0-b183-d23ed28eb61a 'UUID' object has no attribute '_sa_instance_state'
[ERROR] - 2025-02-26 16:29:45,452 - root - 7085d7b6-6fe5-4054-bdf1-75d36e2afb7b 'UUID' object has no attribute '_sa_instance_state'
[ERROR] - 2025-02-26 16:30:33,285 - root - 6649c139-51b2-41af-b917-e678d974278b 'UUID' object has no attribute '_sa_instance_state'
[ERROR] - 2025-02-26 16:32:25,739 - root - 6649c139-51b2-41af-b917-e678d974278b 'UUID' object has no attribute '_sa_instance_state'
[ERROR] - 2025-02-26 16:36:50,583 - root - 807d86ef-d894-4521-99ad-8c282317872d 'UUID' object has no attribute '_sa_instance_state'
[ERROR] - 2025-02-26 16:38:15,433 - root - e415d795-64d5-4fcc-a051-d2bbdce5bf28 'UUID' object has no attribute '_sa_instance_state'
[ERROR] - 2025-02-26 16:38:35,454 - root - e415d795-64d5-4fcc-a051-d2bbdce5bf28 'UUID' object has no attribute '_sa_instance_state'
[ERROR] - 2025-02-26 16:38:58,207 - root - 2aa6fa33-9f05-4688-b17d-a46af938b57b 'UUID' object has no attribute '_sa_instance_state'
[ERROR] - 2025-02-27 15:19:04,106 - root - 4ec1eae4-6619-4bb6-abec-1cde2eb4d90f Mapper 'Mapper[Interface(interface)]' has no property 'tunnel'.  If this property was indicated from other mappers or configure events, ensure registry.configure() has been called.
[ERROR] - 2025-02-27 15:23:44,706 - root - 0fcdc3bd-7caa-49b8-9ec0-b41bc31898fc Mapper 'Mapper[Interface(interface)]' has no property 'tunnel'.  If this property was indicated from other mappers or configure events, ensure registry.configure() has been called.
[ERROR] - 2025-02-27 15:23:54,252 - root - f03aa51a-1b01-49bc-8967-1c3970e450e1 Mapper 'Mapper[Interface(interface)]' has no property 'tunnel'.  If this property was indicated from other mappers or configure events, ensure registry.configure() has been called.
[ERROR] - 2025-02-27 15:31:52,125 - root - 5abde36c-10d2-4364-b3e2-012e8647ef35 Mapper 'Mapper[Interface(interface)]' has no property 'tunnel'.  If this property was indicated from other mappers or configure events, ensure registry.configure() has been called.
[ERROR] - 2025-02-27 16:04:55,287 - root - 67d88930-418a-40b9-837c-f888acca1422 Could not determine join condition between parent/child tables on relationship Interface.tunnel_core - there are multiple foreign key paths linking the tables.  Specify the 'foreign_keys' argument, providing a list of those columns which should be counted as containing a foreign key reference to the parent table.
[ERROR] - 2025-02-27 16:06:54,501 - root - da9ecba7-200a-43bf-97ec-62717c0f7c24 Could not determine join condition between parent/child tables on relationship Tunnel.interface_core - there are multiple foreign key paths linking the tables.  Specify the 'foreign_keys' argument, providing a list of those columns which should be counted as containing a foreign key reference to the parent table.
[ERROR] - 2025-02-27 16:08:46,305 - root - 83a78471-4960-4548-93fd-788a0377256a Mapper 'Mapper[Interface(interface)]' has no property 'tunnel_core_of'.  If this property was indicated from other mappers or configure events, ensure registry.configure() has been called.
[ERROR] - 2025-02-27 16:10:02,525 - root - 1a11b3d3-999e-4da7-a61b-b9b7a8105af8 back_populates on relationship 'Tunnel.interface_core' refers to attribute 'Interface.tunnel_core_of_id' that is not a relationship.  The back_populates parameter should refer to the name of a relationship on the target class.
[ERROR] - 2025-02-27 16:11:00,261 - root - ce818a4f-a9aa-45b4-bb42-8634be82f685 Interface.tunnel_core and back-reference Tunnel.interface_core are both of the same direction <RelationshipDirection.MANYTOONE: 2>.  Did you mean to set remote_side on the many-to-one side ?
[ERROR] - 2025-02-27 16:18:21,589 - root - efa509b1-81eb-4147-87bc-5c1c2c86336e Interface.tunnel_core and back-reference Tunnel.interface_core are both of the same direction <RelationshipDirection.MANYTOONE: 2>.  Did you mean to set remote_side on the many-to-one side ?
[ERROR] - 2025-02-27 16:25:15,340 - root - 2222121b-bbd7-4bec-97ed-6e51bbb36293 Interface.tunnel_core and back-reference Tunnel.interface_core are both of the same direction <RelationshipDirection.MANYTOONE: 2>.  Did you mean to set remote_side on the many-to-one side ?
[ERROR] - 2025-02-27 16:28:29,559 - root - 4aa3f74a-43e2-4c00-94c2-9828542d9187 Interface.tunnel_core and back-reference Tunnel.interface_core are both of the same direction <RelationshipDirection.MANYTOONE: 2>.  Did you mean to set remote_side on the many-to-one side ?
[ERROR] - 2025-02-27 16:32:00,196 - root - fa2346f8-4b35-42f2-8628-389fd09c4eb1 Could not determine join condition between parent/child tables on relationship Interface.tunnel_core - there are multiple foreign key paths linking the tables.  Specify the 'foreign_keys' argument, providing a list of those columns which should be counted as containing a foreign key reference to the parent table.
[ERROR] - 2025-02-27 16:34:41,414 - root - 2f451077-5d62-4e01-9532-7a3f7c8999f1 Could not determine join condition between parent/child tables on relationship Tunnel.interface_core - there are multiple foreign key paths linking the tables.  Specify the 'foreign_keys' argument, providing a list of those columns which should be counted as containing a foreign key reference to the parent table.
[ERROR] - 2025-02-27 16:41:20,932 - root - 2f451077-5d62-4e01-9532-7a3f7c8999f1 One or more mappers failed to initialize - can't proceed with initialization of other mappers. Triggering mapper: 'Mapper[Tunnel(tunnel)]'. Original exception was: Could not determine join condition between parent/child tables on relationship Tunnel.interface_core - there are multiple foreign key paths linking the tables.  Specify the 'foreign_keys' argument, providing a list of those columns which should be counted as containing a foreign key reference to the parent table.
[ERROR] - 2025-02-27 16:42:18,998 - root - 11a78bd6-7c20-4897-b713-c7e3e11c9c95 Mapper 'Mapper[Task(task)]' has no property 'tunnel'.  If this property was indicated from other mappers or configure events, ensure registry.configure() has been called.
[ERROR] - 2025-02-27 16:42:51,904 - root - 7427a19d-13cf-46fe-8e2e-8e67fc9428f4 list index out of range
[ERROR] - 2025-02-27 16:49:24,676 - root - 9ef9cec8-e695-4360-b08a-7d4e6d15fded 'str' object has no attribute 'id'
[ERROR] - 2025-02-27 16:51:04,224 - root - cf45cf66-7cd8-4daf-81d1-b55f2caece0f BaseModel.__init__() takes 1 positional argument but 4 were given
[ERROR] - 2025-02-27 16:52:01,924 - root - b4434043-fe40-4b34-963d-df118e994f07 BaseModel.__init__() takes 1 positional argument but 4 were given
[ERROR] - 2025-02-27 16:53:05,391 - root - c029a1a5-8917-406e-88bb-2501defe3050 3 validation errors for UserPublic
id
  Field required [type=missing, input_value={}, input_type=dict]
    For further information visit https://errors.pydantic.dev/2.7/v/missing
name
  Field required [type=missing, input_value={}, input_type=dict]
    For further information visit https://errors.pydantic.dev/2.7/v/missing
admin
  Field required [type=missing, input_value={}, input_type=dict]
    For further information visit https://errors.pydantic.dev/2.7/v/missing
[ERROR] - 2025-02-27 16:55:05,474 - root - ef3acde6-1708-4f34-983c-3499f4c4b336 (sqlalchemy.dialects.postgresql.asyncpg.Error) <class 'asyncpg.exceptions.DataError'>: invalid input for query argument $7: 0 ('int' object has no attribute 'bytes')
[SQL: INSERT INTO "user" (id, name, password, admin, is_deleted, created_at, created_by, modified_at, modified_by, deleted_at, deleted_by) VALUES ($1::UUID, $2::VARCHAR, $3::VARCHAR, $4::BOOLEAN, $5::BOOLEAN, $6::TIMESTAMP WITHOUT TIME ZONE, $7::UUID, $8::TIMESTAMP WITHOUT TIME ZONE, $9::UUID, $10::TIMESTAMP WITHOUT TIME ZONE, $11::UUID)]
[parameters: (UUID('cfe5c6df-b33a-496a-ae08-8a955a665a94'), 'hanoch', '$2b$12$fui8/9bJecNedSchLkElTep4FZD3rILsNLKkxecw3hxwKi/PKiKY2', True, False, datetime.datetime(2025, 2, 27, 16, 55, 5, 470926), 0, datetime.datetime(2025, 2, 27, 16, 55, 5, 470926), 0, None, UUID('6669b198-36de-4dca-81fe-51a7a86146e9'))]
(Background on this error at: https://sqlalche.me/e/20/dbapi)
[ERROR] - 2025-02-27 16:56:18,664 - root - 7995fac3-0ed5-4f02-a6a7-41d9ee205f9b (sqlalchemy.dialects.postgresql.asyncpg.Error) <class 'asyncpg.exceptions.DataError'>: invalid input for query argument $7: 0 ('int' object has no attribute 'bytes')
[SQL: INSERT INTO "user" (id, name, password, admin, is_deleted, created_at, created_by, modified_at, modified_by, deleted_at, deleted_by) VALUES ($1::UUID, $2::VARCHAR, $3::VARCHAR, $4::BOOLEAN, $5::BOOLEAN, $6::TIMESTAMP WITHOUT TIME ZONE, $7::UUID, $8::TIMESTAMP WITHOUT TIME ZONE, $9::UUID, $10::TIMESTAMP WITHOUT TIME ZONE, $11::UUID)]
[parameters: (UUID('3f307d77-6ee3-4e88-b979-995566a064a3'), 'hanoch', '$2b$12$X31zwLSXrxAM4poWW8511O9praz02DRsAfdnr7XlizMsnzqJh2hUG', True, False, datetime.datetime(2025, 2, 27, 16, 56, 18, 661569), 0, datetime.datetime(2025, 2, 27, 16, 56, 18, 661569), 0, None, UUID('3379cfb8-24b9-4a95-b88d-2892e4a7b5b3'))]
(Background on this error at: https://sqlalche.me/e/20/dbapi)
[ERROR] - 2025-02-27 16:57:09,937 - root - 7995fac3-0ed5-4f02-a6a7-41d9ee205f9b (sqlalchemy.dialects.postgresql.asyncpg.Error) <class 'asyncpg.exceptions.DataError'>: invalid input for query argument $7: 0 ('int' object has no attribute 'bytes')
[SQL: INSERT INTO "user" (id, name, password, admin, is_deleted, created_at, created_by, modified_at, modified_by, deleted_at, deleted_by) VALUES ($1::UUID, $2::VARCHAR, $3::VARCHAR, $4::BOOLEAN, $5::BOOLEAN, $6::TIMESTAMP WITHOUT TIME ZONE, $7::UUID, $8::TIMESTAMP WITHOUT TIME ZONE, $9::UUID, $10::TIMESTAMP WITHOUT TIME ZONE, $11::UUID)]
[parameters: (UUID('1cf65878-5161-4ea0-bba7-28e68b7e57e0'), 'hanoch', '$2b$12$gbthnsWhxd6vArNLPID5JujtsxUT6VqHJNuTukA3MODP2ZGqHBojO', True, False, datetime.datetime(2025, 2, 27, 16, 57, 9, 934541), 0, datetime.datetime(2025, 2, 27, 16, 57, 9, 934541), 0, None, UUID('324c7251-9bd2-47d9-ba51-49932ad4d5ae'))]
(Background on this error at: https://sqlalche.me/e/20/dbapi)
[ERROR] - 2025-03-02 11:31:36,829 - root - 58753c8c-706a-436d-ad57-5d13644b15f7 'UUID' object has no attribute '_sa_instance_state'
[ERROR] - 2025-03-02 11:34:58,939 - root - 4df64d57-8999-4d43-89a8-5c760bef2f7d 'UUID' object has no attribute '_sa_instance_state'
[ERROR] - 2025-03-02 11:42:09,523 - root - 895d20be-954c-4511-a4f6-00a6778102f4 (sqlalchemy.dialects.postgresql.asyncpg.Error) <class 'asyncpg.exceptions.DataError'>: invalid input for query argument $3: IPv4Address('1.2.3.4') (expected str, got IPv4Address)
[SQL: INSERT INTO device (id, name, ip, type, site, is_deleted, created_at, created_by, modified_at, modified_by, deleted_at, deleted_by) VALUES ($1::UUID, $2::VARCHAR, $3::VARCHAR, $4::UUID, $5::UUID, $6::BOOLEAN, $7::TIMESTAMP WITHOUT TIME ZONE, $8::UUID, $9::TIMESTAMP WITHOUT TIME ZONE, $10::UUID, $11::TIMESTAMP WITHOUT TIME ZONE, $12::UUID)]
[parameters: (UUID('9191ed87-c3d6-4335-8eed-4016880c3acd'), 'device1', IPv4Address('1.2.3.4'), UUID('cc459509-b5b1-4026-b0ba-803ac221d2a6'), UUID('5c5514c6-1070-469a-8e5d-0ce38a9ebadd'), False, datetime.datetime(2025, 3, 2, 11, 42, 9, 520151), UUID('51e1ca67-6cb1-467c-b22b-02d72d11473b'), datetime.datetime(2025, 3, 2, 11, 42, 9, 520151), UUID('51e1ca67-6cb1-467c-b22b-02d72d11473b'), None, UUID('21359017-799a-4357-87c0-c8c3b3cbd81e'))]
(Background on this error at: https://sqlalche.me/e/20/dbapi)
[ERROR] - 2025-03-03 10:42:50,999 - root - 8167bdc3-8107-4915-a6bc-2367dac24b97 (sqlalchemy.dialects.postgresql.asyncpg.IntegrityError) <class 'asyncpg.exceptions.ForeignKeyViolationError'>: insert or update on table "device" violates foreign key constraint "device_type_fkey"
DETAIL:  Key (type)=(cc459509-b5b1-4026-b0ba-803ac221d2a6) is not present in table "device_type".
[SQL: INSERT INTO device (id, name, ip, type, site, is_deleted, created_at, created_by, modified_at, modified_by, deleted_at, deleted_by) VALUES ($1::UUID, $2::VARCHAR, $3::VARCHAR, $4::UUID, $5::UUID, $6::BOOLEAN, $7::TIMESTAMP WITHOUT TIME ZONE, $8::UUID, $9::TIMESTAMP WITHOUT TIME ZONE, $10::UUID, $11::TIMESTAMP WITHOUT TIME ZONE, $12::UUID)]
[parameters: (UUID('68856523-5583-4b31-ad6b-0b5edd155860'), 'device1', '1.2.3.4', UUID('cc459509-b5b1-4026-b0ba-803ac221d2a6'), UUID('5c5514c6-1070-469a-8e5d-0ce38a9ebadd'), False, datetime.datetime(2025, 3, 3, 10, 42, 50, 991729), UUID('51e1ca67-6cb1-467c-b22b-02d72d11473b'), datetime.datetime(2025, 3, 3, 10, 42, 50, 991729), UUID('51e1ca67-6cb1-467c-b22b-02d72d11473b'), None, UUID('8bf4dd7d-0534-4639-81ee-b3b1927707c2'))]
(Background on this error at: https://sqlalche.me/e/20/gkpj)
[ERROR] - 2025-03-03 11:49:42,121 - root - 1979bea5-4473-4ae7-a347-f1487b2ff483 (sqlalchemy.dialects.postgresql.asyncpg.ProgrammingError) <class 'asyncpg.exceptions.UndefinedColumnError'>: column "tunnel" of relation "interface" does not exist
[SQL: INSERT INTO interface (id, name, ip, device, tunnel, is_deleted, created_at, created_by, modified_at, modified_by, deleted_at, deleted_by) VALUES ($1::UUID, $2::VARCHAR, $3::VARCHAR, $4::UUID, $5::UUID, $6::BOOLEAN, $7::TIMESTAMP WITHOUT TIME ZONE, $8::UUID, $9::TIMESTAMP WITHOUT TIME ZONE, $10::UUID, $11::TIMESTAMP WITHOUT TIME ZONE, $12::UUID)]
[parameters: (UUID('c81c7276-2ff6-49d2-ac67-422ab6c5fbdd'), 'int1', '198.51.100.1', UUID('75078c57-f9f7-498c-aff1-4529077b27c4'), None, False, datetime.datetime(2025, 3, 3, 11, 49, 42, 116205), UUID('51e1ca67-6cb1-467c-b22b-02d72d11473b'), datetime.datetime(2025, 3, 3, 11, 49, 42, 116205), UUID('51e1ca67-6cb1-467c-b22b-02d72d11473b'), None, None)]
(Background on this error at: https://sqlalche.me/e/20/f405)
[ERROR] - 2025-03-03 12:27:02,753 - root - 55d74809-e9fb-4a23-8398-1b09de7729b6 (sqlalchemy.dialects.postgresql.asyncpg.IntegrityError) <class 'asyncpg.exceptions.ForeignKeyViolationError'>: insert or update on table "tunnel" violates foreign key constraint "tunnel_interface_edge_fkey"
DETAIL:  Key (interface_edge)=(cba8b16a-8641-42d3-8706-1540a4ef293c) is not present in table "interface".
[SQL: INSERT INTO tunnel (id, name, interface_core, interface_edge, reinforced_at, reinforced_by, vendor, is_deleted, created_at, created_by, modified_at, modified_by, deleted_at, deleted_by) VALUES ($1::UUID, $2::VARCHAR, $3::UUID, $4::UUID, $5::TIMESTAMP WITHOUT TIME ZONE, $6::VARCHAR, $7::VARCHAR, $8::BOOLEAN, $9::TIMESTAMP WITHOUT TIME ZONE, $10::UUID, $11::TIMESTAMP WITHOUT TIME ZONE, $12::UUID, $13::TIMESTAMP WITHOUT TIME ZONE, $14::UUID)]
[parameters: (UUID('46296103-f092-4640-bfdf-5a008f65cf66'), 'string', UUID('533e8493-3400-47d4-aaa6-c6fa045a0036'), UUID('cba8b16a-8641-42d3-8706-1540a4ef293c'), None, None, 'tunnel_juniper', False, datetime.datetime(2025, 3, 3, 12, 27, 2, 746352), UUID('1e777a72-d1c7-45fb-9375-e0562e4eb586'), datetime.datetime(2025, 3, 3, 12, 27, 2, 746352), UUID('1e777a72-d1c7-45fb-9375-e0562e4eb586'), None, None)]
(Background on this error at: https://sqlalche.me/e/20/gkpj)
[ERROR] - 2025-03-03 14:09:38,917 - root - be73c354-0d85-4175-9e2e-972d4e65578a (sqlalchemy.dialects.postgresql.asyncpg.IntegrityError) <class 'asyncpg.exceptions.ForeignKeyViolationError'>: insert or update on table "tunnel" violates foreign key constraint "tunnel_interface_edge_fkey"
DETAIL:  Key (interface_edge)=(ceaa2cac-b177-488b-a452-33be990ce203) is not present in table "interface".
[SQL: INSERT INTO tunnel (id, name, interface_core, interface_edge, reinforced_at, reinforced_by, vendor, is_deleted, created_at, created_by, modified_at, modified_by, deleted_at, deleted_by) VALUES ($1::UUID, $2::VARCHAR, $3::UUID, $4::UUID, $5::TIMESTAMP WITHOUT TIME ZONE, $6::VARCHAR, $7::VARCHAR, $8::BOOLEAN, $9::TIMESTAMP WITHOUT TIME ZONE, $10::UUID, $11::TIMESTAMP WITHOUT TIME ZONE, $12::UUID, $13::TIMESTAMP WITHOUT TIME ZONE, $14::UUID)]
[parameters: (UUID('443c81fe-7f27-4770-9192-b51699b50b32'), 'string', UUID('533e8493-3400-47d4-aaa6-c6fa045a0036'), UUID('ceaa2cac-b177-488b-a452-33be990ce203'), None, None, 'tunnel_juniper', False, datetime.datetime(2025, 3, 3, 14, 9, 38, 910489), UUID('1e777a72-d1c7-45fb-9375-e0562e4eb586'), datetime.datetime(2025, 3, 3, 14, 9, 38, 910489), UUID('1e777a72-d1c7-45fb-9375-e0562e4eb586'), None, None)]
(Background on this error at: https://sqlalche.me/e/20/gkpj)
[ERROR] - 2025-03-03 14:14:34,862 - root - c1db440c-1843-4e43-b9e3-7294639acf6c BaseModel.__init__() takes 1 positional argument but 2 were given
[ERROR] - 2025-03-03 14:16:36,675 - root - c1db440c-1843-4e43-b9e3-7294639acf6c BaseModel.__init__() takes 1 positional argument but 2 were given
[ERROR] - 2025-03-03 14:53:26,796 - root - 0d70fa30-e7d3-4cac-aa48-3ff092734b12 (sqlalchemy.dialects.postgresql.asyncpg.Error) <class 'asyncpg.exceptions.DataError'>: invalid input for query argument $1: <built-in function id> ('builtin_function_or_method' object has no attribute 'bytes')
[SQL: SELECT device.id, device.name, device.ip, device.type, device.site, device.is_deleted, device.created_at, device.created_by, device.modified_at, device.modified_by, device.deleted_at, device.deleted_by 
FROM device 
WHERE device.id = $1::UUID]
[parameters: (<built-in function id>,)]
(Background on this error at: https://sqlalche.me/e/20/dbapi)
[ERROR] - 2025-03-03 14:59:13,366 - root - 0d70fa30-e7d3-4cac-aa48-3ff092734b12 (sqlalchemy.dialects.postgresql.asyncpg.Error) <class 'asyncpg.exceptions.DataError'>: invalid input for query argument $1: <built-in function id> ('builtin_function_or_method' object has no attribute 'bytes')
[SQL: SELECT device.id, device.name, device.ip, device.type, device.site, device.is_deleted, device.created_at, device.created_by, device.modified_at, device.modified_by, device.deleted_at, device.deleted_by 
FROM device 
WHERE device.id = $1::UUID]
[parameters: (<built-in function id>,)]
(Background on this error at: https://sqlalche.me/e/20/dbapi)
[ERROR] - 2025-03-03 14:59:47,622 - root - 0d70fa30-e7d3-4cac-aa48-3ff092734b12 (sqlalchemy.dialects.postgresql.asyncpg.Error) <class 'asyncpg.exceptions.DataError'>: invalid input for query argument $1: <built-in function id> ('builtin_function_or_method' object has no attribute 'bytes')
[SQL: SELECT device.id, device.name, device.ip, device.type, device.site, device.is_deleted, device.created_at, device.created_by, device.modified_at, device.modified_by, device.deleted_at, device.deleted_by 
FROM device 
WHERE device.id = $1::UUID]
[parameters: (<built-in function id>,)]
(Background on this error at: https://sqlalche.me/e/20/dbapi)
[ERROR] - 2025-03-03 15:01:45,439 - root - 41e21f71-7825-43ab-8c82-279714aff855 object of type 'UUID' has no len()
[ERROR] - 2025-03-03 15:02:13,808 - root - 41e21f71-7825-43ab-8c82-279714aff855 object of type 'UUID' has no len()
[ERROR] - 2025-03-03 15:03:25,729 - root - 797a79b9-916d-42bd-9a23-631500c9d01a object of type 'UUID' has no len()
[ERROR] - 2025-03-03 15:05:05,170 - root - 797a79b9-916d-42bd-9a23-631500c9d01a object of type 'UUID' has no len()
[ERROR] - 2025-03-03 15:05:10,737 - root - 3af42a4b-c67d-40af-b6f9-e7c5d0e7a9cc (sqlalchemy.dialects.postgresql.asyncpg.Error) <class 'asyncpg.exceptions.DataError'>: invalid input for query argument $1: <built-in function id> ('builtin_function_or_method' object has no attribute 'bytes')
[SQL: SELECT device.id, device.name, device.ip, device.type, device.site, device.is_deleted, device.created_at, device.created_by, device.modified_at, device.modified_by, device.deleted_at, device.deleted_by 
FROM device 
WHERE device.id = $1::UUID]
[parameters: (<built-in function id>,)]
(Background on this error at: https://sqlalche.me/e/20/dbapi)
[ERROR] - 2025-03-03 15:08:51,513 - root - 6b74725f-be7b-42db-8595-bcc191c18b17 (sqlalchemy.dialects.postgresql.asyncpg.Error) <class 'asyncpg.exceptions.DataError'>: invalid input for query argument $1: <built-in function id> ('builtin_function_or_method' object has no attribute 'bytes')
[SQL: SELECT device.id, device.name, device.ip, device.type, device.site, device.is_deleted, device.created_at, device.created_by, device.modified_at, device.modified_by, device.deleted_at, device.deleted_by 
FROM device 
WHERE device.id = $1::UUID]
[parameters: (<built-in function id>,)]
(Background on this error at: https://sqlalche.me/e/20/dbapi)
[ERROR] - 2025-03-03 15:10:50,069 - root - 6b74725f-be7b-42db-8595-bcc191c18b17 (sqlalchemy.dialects.postgresql.asyncpg.Error) <class 'asyncpg.exceptions.DataError'>: invalid input for query argument $1: <built-in function id> ('builtin_function_or_method' object has no attribute 'bytes')
[SQL: SELECT device.id, device.name, device.ip, device.type, device.site, device.is_deleted, device.created_at, device.created_by, device.modified_at, device.modified_by, device.deleted_at, device.deleted_by 
FROM device 
WHERE device.id = $1::UUID]
[parameters: (<built-in function id>,)]
(Background on this error at: https://sqlalche.me/e/20/dbapi)
[ERROR] - 2025-03-03 15:10:54,305 - root - 33b105a0-bcc3-4e6b-b883-d8c9565653a5 BaseModel.__init__() takes 1 positional argument but 2 were given
[ERROR] - 2025-03-03 15:12:11,830 - root - 33b105a0-bcc3-4e6b-b883-d8c9565653a5 BaseModel.__init__() takes 1 positional argument but 2 were given
[ERROR] - 2025-03-03 15:12:15,677 - root - 207765f1-a589-46f3-92c5-ab84d6e51bae 2 validation errors for DevicePublic
type_id
  UUID input should be a string, bytes or UUID object [type=uuid_type, input_value=None, input_type=NoneType]
    For further information visit https://errors.pydantic.dev/2.7/v/uuid_type
site_id
  UUID input should be a string, bytes or UUID object [type=uuid_type, input_value=None, input_type=NoneType]
    For further information visit https://errors.pydantic.dev/2.7/v/uuid_type
[ERROR] - 2025-03-03 15:16:03,488 - root - a38b20a6-ab21-4706-86b4-a92069712e85 2 validation errors for DevicePublic
type_id
  UUID input should be a string, bytes or UUID object [type=uuid_type, input_value=None, input_type=NoneType]
    For further information visit https://errors.pydantic.dev/2.7/v/uuid_type
site_id
  UUID input should be a string, bytes or UUID object [type=uuid_type, input_value=None, input_type=NoneType]
    For further information visit https://errors.pydantic.dev/2.7/v/uuid_type
[ERROR] - 2025-03-03 15:44:54,663 - root - 32f6bb88-d2a8-4ae3-a4d1-035fa0571fb7 Instance '<Device at 0x279c2d39690>' is not persistent within this Session
[ERROR] - 2025-03-03 15:47:21,266 - root - 2054959b-a6fe-4109-9732-86e94cf0e205 Instance '<Device at 0x21f72845550>' is not persistent within this Session
